Traceback (most recent call last):
  File "C:\Users\dude0\PycharmProjects\snipething\venv\lib\site-packages\urllib3\connection.py", line 169, in _new_conn
    conn = connection.create_connection(
  File "C:\Users\dude0\PycharmProjects\snipething\venv\lib\site-packages\urllib3\util\connection.py", line 96, in create_connection
    raise err
  File "C:\Users\dude0\PycharmProjects\snipething\venv\lib\site-packages\urllib3\util\connection.py", line 86, in create_connection
    sock.connect(sa)
TimeoutError: [WinError 10060] A connection attempt failed because the connected party did not properly respond after a period of time, or established connection failed because connected host has failed to respond

During handling of the above exception, another exception occurred:

Traceback (most recent call last):
  File "C:\Users\dude0\PycharmProjects\snipething\venv\lib\site-packages\urllib3\connectionpool.py", line 699, in urlopen
    httplib_response = self._make_request(
  File "C:\Users\dude0\PycharmProjects\snipething\venv\lib\site-packages\urllib3\connectionpool.py", line 382, in _make_request
    self._validate_conn(conn)
  File "C:\Users\dude0\PycharmProjects\snipething\venv\lib\site-packages\urllib3\connectionpool.py", line 1010, in _validate_conn
    conn.connect()
  File "C:\Users\dude0\PycharmProjects\snipething\venv\lib\site-packages\urllib3\connection.py", line 353, in connect
    conn = self._new_conn()
  File "C:\Users\dude0\PycharmProjects\snipething\venv\lib\site-packages\urllib3\connection.py", line 181, in _new_conn
    raise NewConnectionError(
urllib3.exceptions.NewConnectionError: <urllib3.connection.HTTPSConnection object at 0x045F31A8>: Failed to establish a new connection: [WinError 10060] A connection attempt failed because the connected party did not properly respond after a period of time, or established connection failed because connected host has failed to respond

During handling of the above exception, another exception occurred:

Traceback (most recent call last):
  File "C:\Users\dude0\PycharmProjects\snipething\venv\lib\site-packages\requests\adapters.py", line 439, in send
    resp = conn.urlopen(
  File "C:\Users\dude0\PycharmProjects\snipething\venv\lib\site-packages\urllib3\connectionpool.py", line 755, in urlopen
    retries = retries.increment(
  File "C:\Users\dude0\PycharmProjects\snipething\venv\lib\site-packages\urllib3\util\retry.py", line 574, in increment
    raise MaxRetryError(_pool, url, error or ResponseError(cause))
urllib3.exceptions.MaxRetryError: HTTPSConnectionPool(host='catalog.roblox.com', port=443): Max retries exceeded with url: /v1/catalog/items/details (Caused by NewConnectionError('<urllib3.connection.HTTPSConnection object at 0x045F31A8>: Failed to establish a new connection: [WinError 10060] A connection attempt failed because the connected party did not properly respond after a period of time, or established connection failed because connected host has failed to respond'))

During handling of the above exception, another exception occurred:

Traceback (most recent call last):
  File "C:/Users/dude0/PycharmProjects/snipething/main.py", line 155, in <module>
    headers = makenewCSRF(cookies)
  File "C:/Users/dude0/PycharmProjects/snipething/main.py", line 134, in makenewCSRF
    postRequest = requests.post('https://catalog.roblox.com/v1/catalog/items/details',cookies = cookie)
  File "C:\Users\dude0\PycharmProjects\snipething\venv\lib\site-packages\requests\api.py", line 117, in post
    return request('post', url, data=data, json=json, **kwargs)
  File "C:\Users\dude0\PycharmProjects\snipething\venv\lib\site-packages\requests\api.py", line 61, in request
    return session.request(method=method, url=url, **kwargs)
  File "C:\Users\dude0\PycharmProjects\snipething\venv\lib\site-packages\requests\sessions.py", line 542, in request
    resp = self.send(prep, **send_kwargs)
  File "C:\Users\dude0\PycharmProjects\snipething\venv\lib\site-packages\requests\sessions.py", line 655, in send
    r = adapter.send(request, **kwargs)
  File "C:\Users\dude0\PycharmProjects\snipething\venv\lib\site-packages\requests\adapters.py", line 516, in send
    raise ConnectionError(e, request=request)
requests.exceptions.ConnectionError: HTTPSConnectionPool(host='catalog.roblox.com', port=443): Max retries exceeded with url: /v1/catalog/items/details (Caused by NewConnectionError('<urllib3.connection.HTTPSConnection object at 0x045F31A8>: Failed to establish a new connection: [WinError 10060] A connection attempt failed because the connected party did not properly respond after a period of time, or established connection failed because connected host has failed to respond'))




